2020-08-20 18:33:59,431 ERROR: Exception on /index [GET] [in c:\users\stan\appdata\local\programs\python\python37\lib\site-packages\flask\app.py:1891]
Traceback (most recent call last):
  File "c:\users\stan\appdata\local\programs\python\python37\lib\site-packages\flask\app.py", line 2446, in wsgi_app
    response = self.full_dispatch_request()
  File "c:\users\stan\appdata\local\programs\python\python37\lib\site-packages\flask\app.py", line 1951, in full_dispatch_request
    rv = self.handle_user_exception(e)
  File "c:\users\stan\appdata\local\programs\python\python37\lib\site-packages\flask\app.py", line 1820, in handle_user_exception
    reraise(exc_type, exc_value, tb)
  File "c:\users\stan\appdata\local\programs\python\python37\lib\site-packages\flask\_compat.py", line 39, in reraise
    raise value
  File "c:\users\stan\appdata\local\programs\python\python37\lib\site-packages\flask\app.py", line 1949, in full_dispatch_request
    rv = self.dispatch_request()
  File "c:\users\stan\appdata\local\programs\python\python37\lib\site-packages\flask\app.py", line 1935, in dispatch_request
    return self.view_functions[rule.endpoint](**req.view_args)
  File "c:\users\stan\appdata\local\programs\python\python37\lib\site-packages\flask_login\utils.py", line 271, in decorated_view
    return current_app.login_manager.unauthorized()
  File "c:\users\stan\appdata\local\programs\python\python37\lib\site-packages\flask_login\login_manager.py", line 174, in unauthorized
    redirect_url = make_login_url(login_view, next_url=request.url)
  File "c:\users\stan\appdata\local\programs\python\python37\lib\site-packages\flask_login\utils.py", line 120, in login_url
    base = expand_login_view(login_view)
  File "c:\users\stan\appdata\local\programs\python\python37\lib\site-packages\flask_login\utils.py", line 97, in expand_login_view
    return url_for(login_view)
  File "c:\users\stan\appdata\local\programs\python\python37\lib\site-packages\flask\helpers.py", line 370, in url_for
    return appctx.app.handle_url_build_error(error, endpoint, values)
  File "c:\users\stan\appdata\local\programs\python\python37\lib\site-packages\flask\app.py", line 2215, in handle_url_build_error
    reraise(exc_type, exc_value, tb)
  File "c:\users\stan\appdata\local\programs\python\python37\lib\site-packages\flask\_compat.py", line 39, in reraise
    raise value
  File "c:\users\stan\appdata\local\programs\python\python37\lib\site-packages\flask\helpers.py", line 358, in url_for
    endpoint, values, method=method, force_external=external
  File "c:\users\stan\appdata\local\programs\python\python37\lib\site-packages\werkzeug\routing.py", line 2020, in build
    raise BuildError(endpoint, values, method, self)
werkzeug.routing.BuildError: Could not build url for endpoint 'login'. Did you mean 'auth.login' instead?
2020-08-20 18:39:09,925 INFO: Microblog startup [in C:\Users\Stan\Desktop\dev\microblog\app\__init__.py:74]
2020-08-20 18:39:12,362 ERROR: Exception on /index [GET] [in c:\users\stan\appdata\local\programs\python\python37\lib\site-packages\flask\app.py:1891]
Traceback (most recent call last):
  File "c:\users\stan\appdata\local\programs\python\python37\lib\site-packages\flask\app.py", line 2446, in wsgi_app
    response = self.full_dispatch_request()
  File "c:\users\stan\appdata\local\programs\python\python37\lib\site-packages\flask\app.py", line 1951, in full_dispatch_request
    rv = self.handle_user_exception(e)
  File "c:\users\stan\appdata\local\programs\python\python37\lib\site-packages\flask\app.py", line 1820, in handle_user_exception
    reraise(exc_type, exc_value, tb)
  File "c:\users\stan\appdata\local\programs\python\python37\lib\site-packages\flask\_compat.py", line 39, in reraise
    raise value
  File "c:\users\stan\appdata\local\programs\python\python37\lib\site-packages\flask\app.py", line 1949, in full_dispatch_request
    rv = self.dispatch_request()
  File "c:\users\stan\appdata\local\programs\python\python37\lib\site-packages\flask\app.py", line 1935, in dispatch_request
    return self.view_functions[rule.endpoint](**req.view_args)
  File "c:\users\stan\appdata\local\programs\python\python37\lib\site-packages\flask_login\utils.py", line 271, in decorated_view
    return current_app.login_manager.unauthorized()
  File "c:\users\stan\appdata\local\programs\python\python37\lib\site-packages\flask_login\login_manager.py", line 174, in unauthorized
    redirect_url = make_login_url(login_view, next_url=request.url)
  File "c:\users\stan\appdata\local\programs\python\python37\lib\site-packages\flask_login\utils.py", line 120, in login_url
    base = expand_login_view(login_view)
  File "c:\users\stan\appdata\local\programs\python\python37\lib\site-packages\flask_login\utils.py", line 97, in expand_login_view
    return url_for(login_view)
  File "c:\users\stan\appdata\local\programs\python\python37\lib\site-packages\flask\helpers.py", line 370, in url_for
    return appctx.app.handle_url_build_error(error, endpoint, values)
  File "c:\users\stan\appdata\local\programs\python\python37\lib\site-packages\flask\app.py", line 2215, in handle_url_build_error
    reraise(exc_type, exc_value, tb)
  File "c:\users\stan\appdata\local\programs\python\python37\lib\site-packages\flask\_compat.py", line 39, in reraise
    raise value
  File "c:\users\stan\appdata\local\programs\python\python37\lib\site-packages\flask\helpers.py", line 358, in url_for
    endpoint, values, method=method, force_external=external
  File "c:\users\stan\appdata\local\programs\python\python37\lib\site-packages\werkzeug\routing.py", line 2020, in build
    raise BuildError(endpoint, values, method, self)
werkzeug.routing.BuildError: Could not build url for endpoint 'main.login'. Did you mean 'auth.login' instead?
2020-08-20 18:39:14,146 ERROR: Exception on /index [GET] [in c:\users\stan\appdata\local\programs\python\python37\lib\site-packages\flask\app.py:1891]
Traceback (most recent call last):
  File "c:\users\stan\appdata\local\programs\python\python37\lib\site-packages\flask\app.py", line 2446, in wsgi_app
    response = self.full_dispatch_request()
  File "c:\users\stan\appdata\local\programs\python\python37\lib\site-packages\flask\app.py", line 1951, in full_dispatch_request
    rv = self.handle_user_exception(e)
  File "c:\users\stan\appdata\local\programs\python\python37\lib\site-packages\flask\app.py", line 1820, in handle_user_exception
    reraise(exc_type, exc_value, tb)
  File "c:\users\stan\appdata\local\programs\python\python37\lib\site-packages\flask\_compat.py", line 39, in reraise
    raise value
  File "c:\users\stan\appdata\local\programs\python\python37\lib\site-packages\flask\app.py", line 1949, in full_dispatch_request
    rv = self.dispatch_request()
  File "c:\users\stan\appdata\local\programs\python\python37\lib\site-packages\flask\app.py", line 1935, in dispatch_request
    return self.view_functions[rule.endpoint](**req.view_args)
  File "c:\users\stan\appdata\local\programs\python\python37\lib\site-packages\flask_login\utils.py", line 271, in decorated_view
    return current_app.login_manager.unauthorized()
  File "c:\users\stan\appdata\local\programs\python\python37\lib\site-packages\flask_login\login_manager.py", line 174, in unauthorized
    redirect_url = make_login_url(login_view, next_url=request.url)
  File "c:\users\stan\appdata\local\programs\python\python37\lib\site-packages\flask_login\utils.py", line 120, in login_url
    base = expand_login_view(login_view)
  File "c:\users\stan\appdata\local\programs\python\python37\lib\site-packages\flask_login\utils.py", line 97, in expand_login_view
    return url_for(login_view)
  File "c:\users\stan\appdata\local\programs\python\python37\lib\site-packages\flask\helpers.py", line 370, in url_for
    return appctx.app.handle_url_build_error(error, endpoint, values)
  File "c:\users\stan\appdata\local\programs\python\python37\lib\site-packages\flask\app.py", line 2215, in handle_url_build_error
    reraise(exc_type, exc_value, tb)
  File "c:\users\stan\appdata\local\programs\python\python37\lib\site-packages\flask\_compat.py", line 39, in reraise
    raise value
  File "c:\users\stan\appdata\local\programs\python\python37\lib\site-packages\flask\helpers.py", line 358, in url_for
    endpoint, values, method=method, force_external=external
  File "c:\users\stan\appdata\local\programs\python\python37\lib\site-packages\werkzeug\routing.py", line 2020, in build
    raise BuildError(endpoint, values, method, self)
werkzeug.routing.BuildError: Could not build url for endpoint 'main.login'. Did you mean 'auth.login' instead?
