2020-08-30 19:30:13,661 ERROR: Exception on /search [GET] [in c:\users\stan\appdata\local\programs\python\python37\lib\site-packages\flask\app.py:1891]
Traceback (most recent call last):
  File "c:\users\stan\appdata\local\programs\python\python37\lib\site-packages\urllib3\connection.py", line 160, in _new_conn
    (self._dns_host, self.port), self.timeout, **extra_kw
  File "c:\users\stan\appdata\local\programs\python\python37\lib\site-packages\urllib3\util\connection.py", line 84, in create_connection
    raise err
  File "c:\users\stan\appdata\local\programs\python\python37\lib\site-packages\urllib3\util\connection.py", line 74, in create_connection
    sock.connect(sa)
ConnectionRefusedError: [WinError 10061] No se puede establecer una conexión ya que el equipo de destino denegó expresamente dicha conexión

During handling of the above exception, another exception occurred:

Traceback (most recent call last):
  File "c:\users\stan\appdata\local\programs\python\python37\lib\site-packages\elasticsearch\connection\http_urllib3.py", line 246, in perform_request
    method, url, body, retries=Retry(False), headers=request_headers, **kw
  File "c:\users\stan\appdata\local\programs\python\python37\lib\site-packages\urllib3\connectionpool.py", line 725, in urlopen
    method, url, error=e, _pool=self, _stacktrace=sys.exc_info()[2]
  File "c:\users\stan\appdata\local\programs\python\python37\lib\site-packages\urllib3\util\retry.py", line 379, in increment
    raise six.reraise(type(error), error, _stacktrace)
  File "c:\users\stan\appdata\local\programs\python\python37\lib\site-packages\urllib3\packages\six.py", line 735, in reraise
    raise value
  File "c:\users\stan\appdata\local\programs\python\python37\lib\site-packages\urllib3\connectionpool.py", line 677, in urlopen
    chunked=chunked,
  File "c:\users\stan\appdata\local\programs\python\python37\lib\site-packages\urllib3\connectionpool.py", line 392, in _make_request
    conn.request(method, url, **httplib_request_kw)
  File "c:\users\stan\appdata\local\programs\python\python37\lib\http\client.py", line 1244, in request
    self._send_request(method, url, body, headers, encode_chunked)
  File "c:\users\stan\appdata\local\programs\python\python37\lib\http\client.py", line 1290, in _send_request
    self.endheaders(body, encode_chunked=encode_chunked)
  File "c:\users\stan\appdata\local\programs\python\python37\lib\http\client.py", line 1239, in endheaders
    self._send_output(message_body, encode_chunked=encode_chunked)
  File "c:\users\stan\appdata\local\programs\python\python37\lib\http\client.py", line 1026, in _send_output
    self.send(msg)
  File "c:\users\stan\appdata\local\programs\python\python37\lib\http\client.py", line 966, in send
    self.connect()
  File "c:\users\stan\appdata\local\programs\python\python37\lib\site-packages\urllib3\connection.py", line 187, in connect
    conn = self._new_conn()
  File "c:\users\stan\appdata\local\programs\python\python37\lib\site-packages\urllib3\connection.py", line 172, in _new_conn
    self, "Failed to establish a new connection: %s" % e
urllib3.exceptions.NewConnectionError: <urllib3.connection.HTTPConnection object at 0x00000207EC4A0E48>: Failed to establish a new connection: [WinError 10061] No se puede establecer una conexión ya que el equipo de destino denegó expresamente dicha conexión

During handling of the above exception, another exception occurred:

Traceback (most recent call last):
  File "c:\users\stan\appdata\local\programs\python\python37\lib\site-packages\flask\app.py", line 2446, in wsgi_app
    response = self.full_dispatch_request()
  File "c:\users\stan\appdata\local\programs\python\python37\lib\site-packages\flask\app.py", line 1951, in full_dispatch_request
    rv = self.handle_user_exception(e)
  File "c:\users\stan\appdata\local\programs\python\python37\lib\site-packages\flask\app.py", line 1820, in handle_user_exception
    reraise(exc_type, exc_value, tb)
  File "c:\users\stan\appdata\local\programs\python\python37\lib\site-packages\flask\_compat.py", line 39, in reraise
    raise value
  File "c:\users\stan\appdata\local\programs\python\python37\lib\site-packages\flask\app.py", line 1949, in full_dispatch_request
    rv = self.dispatch_request()
  File "c:\users\stan\appdata\local\programs\python\python37\lib\site-packages\flask\app.py", line 1935, in dispatch_request
    return self.view_functions[rule.endpoint](**req.view_args)
  File "c:\users\stan\appdata\local\programs\python\python37\lib\site-packages\flask_login\utils.py", line 272, in decorated_view
    return func(*args, **kwargs)
  File "C:\Users\Stan\Desktop\dev\microblog\app\main\routes.py", line 146, in search
    current_app.config['POST_PER_PAGE'])
  File "C:\Users\Stan\Desktop\dev\microblog\app\models.py", line 15, in search
    ids, total = query_index(cls.__tablename__, expression, page, per_page)
  File "C:\Users\Stan\Desktop\dev\microblog\app\search.py", line 25, in query_index
    'from': (page - 1) * per_page, 'size': per_page})
  File "c:\users\stan\appdata\local\programs\python\python37\lib\site-packages\elasticsearch\client\utils.py", line 152, in _wrapped
    return func(*args, params=params, headers=headers, **kwargs)
  File "c:\users\stan\appdata\local\programs\python\python37\lib\site-packages\elasticsearch\client\__init__.py", line 1617, in search
    body=body,
  File "c:\users\stan\appdata\local\programs\python\python37\lib\site-packages\elasticsearch\transport.py", line 390, in perform_request
    raise e
  File "c:\users\stan\appdata\local\programs\python\python37\lib\site-packages\elasticsearch\transport.py", line 365, in perform_request
    timeout=timeout,
  File "c:\users\stan\appdata\local\programs\python\python37\lib\site-packages\elasticsearch\connection\http_urllib3.py", line 258, in perform_request
    raise ConnectionError("N/A", str(e), e)
elasticsearch.exceptions.ConnectionError: ConnectionError(<urllib3.connection.HTTPConnection object at 0x00000207EC4A0E48>: Failed to establish a new connection: [WinError 10061] No se puede establecer una conexión ya que el equipo de destino denegó expresamente dicha conexión) caused by: NewConnectionError(<urllib3.connection.HTTPConnection object at 0x00000207EC4A0E48>: Failed to establish a new connection: [WinError 10061] No se puede establecer una conexión ya que el equipo de destino denegó expresamente dicha conexión)
2020-08-30 19:30:52,471 ERROR: Exception on /search [GET] [in c:\users\stan\appdata\local\programs\python\python37\lib\site-packages\flask\app.py:1891]
Traceback (most recent call last):
  File "c:\users\stan\appdata\local\programs\python\python37\lib\site-packages\flask\app.py", line 2446, in wsgi_app
    response = self.full_dispatch_request()
  File "c:\users\stan\appdata\local\programs\python\python37\lib\site-packages\flask\app.py", line 1951, in full_dispatch_request
    rv = self.handle_user_exception(e)
  File "c:\users\stan\appdata\local\programs\python\python37\lib\site-packages\flask\app.py", line 1820, in handle_user_exception
    reraise(exc_type, exc_value, tb)
  File "c:\users\stan\appdata\local\programs\python\python37\lib\site-packages\flask\_compat.py", line 39, in reraise
    raise value
  File "c:\users\stan\appdata\local\programs\python\python37\lib\site-packages\flask\app.py", line 1949, in full_dispatch_request
    rv = self.dispatch_request()
  File "c:\users\stan\appdata\local\programs\python\python37\lib\site-packages\flask\app.py", line 1935, in dispatch_request
    return self.view_functions[rule.endpoint](**req.view_args)
  File "c:\users\stan\appdata\local\programs\python\python37\lib\site-packages\flask_login\utils.py", line 272, in decorated_view
    return func(*args, **kwargs)
  File "C:\Users\Stan\Desktop\dev\microblog\app\main\routes.py", line 146, in search
    current_app.config['POST_PER_PAGE'])
  File "C:\Users\Stan\Desktop\dev\microblog\app\models.py", line 15, in search
    ids, total = query_index(cls.__tablename__, expression, page, per_page)
  File "C:\Users\Stan\Desktop\dev\microblog\app\search.py", line 25, in query_index
    'from': (page - 1) * per_page, 'size': per_page})
  File "c:\users\stan\appdata\local\programs\python\python37\lib\site-packages\elasticsearch\client\utils.py", line 152, in _wrapped
    return func(*args, params=params, headers=headers, **kwargs)
  File "c:\users\stan\appdata\local\programs\python\python37\lib\site-packages\elasticsearch\client\__init__.py", line 1617, in search
    body=body,
  File "c:\users\stan\appdata\local\programs\python\python37\lib\site-packages\elasticsearch\transport.py", line 390, in perform_request
    raise e
  File "c:\users\stan\appdata\local\programs\python\python37\lib\site-packages\elasticsearch\transport.py", line 365, in perform_request
    timeout=timeout,
  File "c:\users\stan\appdata\local\programs\python\python37\lib\site-packages\elasticsearch\connection\http_urllib3.py", line 269, in perform_request
    self._raise_error(response.status, raw_data)
  File "c:\users\stan\appdata\local\programs\python\python37\lib\site-packages\elasticsearch\connection\base.py", line 301, in _raise_error
    status_code, error_message, additional_info
elasticsearch.exceptions.TransportError: TransportError(503, 'search_phase_execution_exception')
